2025-05-30 11:51:16,190 ERROR scheduler Exception in Enqueue Events for Site nexchar.local
Traceback (most recent call last):
  File "/Users/shobhit/Nexchar-bench/nexchar-bench/apps/frappe/frappe/utils/scheduler.py", line 99, in enqueue_events_for_site
    if is_scheduler_inactive():
  File "/Users/shobhit/Nexchar-bench/nexchar-bench/apps/frappe/frappe/utils/scheduler.py", line 143, in is_scheduler_inactive
    if is_scheduler_disabled(verbose=verbose):
  File "/Users/shobhit/Nexchar-bench/nexchar-bench/apps/frappe/frappe/utils/scheduler.py", line 156, in is_scheduler_disabled
    frappe.db.get_single_value("System Settings", "enable_scheduler")
  File "/Users/shobhit/Nexchar-bench/nexchar-bench/apps/frappe/frappe/database/database.py", line 837, in get_single_value
    ).run()
  File "/Users/shobhit/Nexchar-bench/nexchar-bench/apps/frappe/frappe/query_builder/utils.py", line 87, in execute_query
    result = frappe.db.sql(query, params, *args, **kwargs)  # nosemgrep
  File "/Users/shobhit/Nexchar-bench/nexchar-bench/apps/frappe/frappe/database/database.py", line 230, in sql
    self._cursor.execute(query, values)
  File "/Users/shobhit/Nexchar-bench/nexchar-bench/env/lib/python3.10/site-packages/pymysql/cursors.py", line 153, in execute
    result = self._query(query)
  File "/Users/shobhit/Nexchar-bench/nexchar-bench/env/lib/python3.10/site-packages/pymysql/cursors.py", line 322, in _query
    conn.query(q)
  File "/Users/shobhit/Nexchar-bench/nexchar-bench/env/lib/python3.10/site-packages/pymysql/connections.py", line 563, in query
    self._affected_rows = self._read_query_result(unbuffered=unbuffered)
  File "/Users/shobhit/Nexchar-bench/nexchar-bench/env/lib/python3.10/site-packages/pymysql/connections.py", line 825, in _read_query_result
    result.read()
  File "/Users/shobhit/Nexchar-bench/nexchar-bench/env/lib/python3.10/site-packages/pymysql/connections.py", line 1199, in read
    first_packet = self.connection._read_packet()
  File "/Users/shobhit/Nexchar-bench/nexchar-bench/env/lib/python3.10/site-packages/pymysql/connections.py", line 775, in _read_packet
    packet.raise_for_error()
  File "/Users/shobhit/Nexchar-bench/nexchar-bench/env/lib/python3.10/site-packages/pymysql/protocol.py", line 219, in raise_for_error
    err.raise_mysql_exception(self._data)
  File "/Users/shobhit/Nexchar-bench/nexchar-bench/env/lib/python3.10/site-packages/pymysql/err.py", line 150, in raise_mysql_exception
    raise errorclass(errno, errval)
pymysql.err.ProgrammingError: (1146, "Table '_6c8a96326ab68a59.tabsingles' doesn't exist")
